Workbook

Sheet Riesgos
A1: ID | B1: Riesgo (dado que… puede ocurrir que…) | C1: Categoría | D1: P | E1: I | F1: E | G1: Justificación de P e I | H1: Mitigación (reducción) | I1: Contingencia | J1: Disparador | K1: Responsable | L1: Gestión
A2: R01 | B2: Dado que cada módulo tiene un único responsable, los seis integrantes trabajan y los sprints de implementación duran una semana, puede ocurrir que una semana de poca disponibilidad deje un módulo sin avanzar y haya que recortar HU de ese módulo antes del 15/11. | C2: Proyecto | D2: 0.6 | E2: 3 | F2: =D2*E2 | G2: P: el Sprint 0 ya cerró después de G0 (07/10) y no hay margen entre sprints. Impacto: perder una de las tres semanas de implementación de un módulo equivale a una semana de trabajo de una persona. | H2: Cada responsable declara su disponibilidad en la daily de inicio de sprint (2 min). Cada módulo define de antemano su mínimo viable (ABM y flujo principal) y deja listados y reporte para el final. Las specs de las HU quedan listas en el Sprint 1 para que el agente implemente sin esperar. | I2: Se recortan primero las HU de prioridad baja del módulo afectado y otro integrante con carga liviana toma la HU crítica con apoyo del agente. | J2: Al cierre del Sprint 2 (28/10) un módulo no tiene sus ABM en Done, o una persona avisa que no podrá dedicar el sprint. | K2: Franco Martín Soler | L2: Activa
A3: R02 | B3: Dado que los PR generados por agentes de IA los revisa otro integrante que también trabaja, puede ocurrir que las revisiones sean superficiales o se demoren y entren a develop defectos que aparezcan recién en las pruebas de integración del Sprint 4. | C3: Proyecto | D3: 0.6 | E3: 3 | F3: =D3*E3 | G3: P: seis PR por sprint de una semana y revisores con poco tiempo; el plan lo lista como riesgo propio del uso de IA. Impacto: un defecto hallado en el Sprint 4 en un flujo compartido (comanda, factura) se corrige con una semana por delante. | H3: PR chicos (una HU por PR). La CI (lint, tests e import-linter) es condición para mergear, así la revisión humana se centra en la lógica. Checklist de 5 puntos en la plantilla de PR: criterio de aceptación probado, nada no pedido, reglas de capas, nombres y tests. Revisor rotativo. | I3: Revisión cruzada de 1 hora por módulo al inicio del Sprint 4 sobre los PR ya integrados, priorizando Comanda, Factura y Reserva. | J3: Un PR lleva más de 24 h sin revisar, se mergea sin ningún comentario sobre la lógica, o aparece en develop un bug de un PR ya integrado. | K3: Héctor Sánchez | L3: Activa
A4: R03 | B4: Dado que el Sprint 1 junta en dos semanas tareas manuales y documentales (Puntos de Función con 14 factores justificados, estándares, criterios de conformidad, casos de prueba, GitFlow y CI) y el Sprint 0 terminó con atraso, puede ocurrir que el Sprint 1 pase del 21/10 y consuma parte del Sprint 2, que dura una sola semana. | C4: Proyecto | D4: 0.5 | E4: 3 | F4: =D4*E4 | G4: P: el Sprint 0 cerró después de G0 y el Sprint 1 tiene más tareas que el 0. Impacto: cada día de corrimiento recorta cerca de 5 % de las tres semanas de implementación. | H4: Priorizar en el Sprint 1 lo que bloquea la implementación (estándares, AGENTS.md, esqueletos y CI). Los Puntos de Función se reparten por módulo con una plantilla única y los 14 factores se discuten una sola vez en grupo. Revisar el avance a mitad de sprint (14/10). | I4: Pasar al Sprint 2 con lo mínimo (estándares, AGENTS.md, esqueletos, CI) y terminar PF y criterios de conformidad en paralelo durante el Sprint 2. | J4: El 14/10 menos de la mitad de las tareas del Sprint 1 está en Done, o en G1 (21/10) falta alguna de S1-01 a S1-05. | K4: Federico Cabaña | L4: Activa
A5: R04 | B5: Dado que Comanda (M4) es la base de Reservas (crear comanda con reserva), de Pagos (factura de la comanda) y de cuatro reportes, puede ocurrir que un atraso de M4 deje a M5 y M6 sin poder probar sus flujos y la integración se acumule en el Sprint 4. | C5: Proyecto | D5: 0.5 | E5: 3 | F5: =D5*E5 | G5: P: M4 tiene el ciclo de vida más largo (10 RF). Impacto: bloquea dos módulos y cuatro reportes. | H5: Congelar en el Sprint 1 el contrato de Comanda y DetalleComanda (esquemas y endpoints, ya definidos en el diagrama) y dejar un stub compartido para que M5 y M6 prueben sin esperar. M4 implementa primero crear, cerrar y consultar comanda. | I5: Otro integrante con carga liviana (M2 o M5) toma las HU secundarias de M4 (listados, modificar) para que M4 se concentre en el flujo crítico. | J5: Al cierre del Sprint 2 (28/10) Comanda no tiene funcionando crear, cerrar y consultar. | K5: Juan Ignacio Riquelme | L5: Activa
A6: R05 | B6: Dado que la entrega es el 15/11 y el Sprint 4 concentra reportes, integración entre módulos y correcciones, puede ocurrir que las pruebas de integración se dejen para el final y los defectos hallados no se alcancen a corregir en los 4 días de cierre. | C6: Proyecto | D6: 0.5 | E6: 3 | F6: =D6*E6 | G6: P: sin semana de colchón después del Sprint 4. Impacto: defectos en flujos centrales sin tiempo de corrección dejan HU obligatorias fallando. | H6: Cada HU se entrega con sus pruebas en el mismo PR (RNF-MAN-04) y la CI corre la suite completa. En G2 (06/11) se corre un flujo completo reserva → comanda → factura → cobro con datos semilla; en el Sprint 4 solo se corrige. | I6: Congelar funcionalidad nueva el 08/11 y dedicar el resto del Sprint 4 y el cierre a corregir flujos centrales; los reportes menos críticos se entregan con defectos conocidos documentados. | J6: En G2 (06/11) el flujo completo no corre de punta a punta, o la cobertura queda bajo el umbral de RNF-MAN-04. | K6: Giuliano Giannoncelli | L6: Activa
A7: R06 | B7: Dado que la consigna no define varios comportamientos y el equipo los resolvió con supuestos propios, puede ocurrir que en una review o en la entrega la cátedra espere otro comportamiento y haya que cambiar flujos de uno o dos módulos sin tiempo de rehacerlos. | C7: Negocio | D7: 0.4 | E7: 3 | F7: =D7*E7 | G7: P: solo se detecta cuando un docente lo ve; G1 y G2 son la oportunidad. Impacto: cambiar reglas ya implementadas toca servicio, pruebas y pantalla, y si ocurre en el Sprint 4 no hay tiempo. | H7: Reunir en un solo documento los supuestos marcados «Supuesto:» en HU, RNF y arquitectura, y llevarlos a G1 (21/10) para que Schanz o Urrutia los confirmen o corrijan (1 h en total). | I7: Ajustar la regla en el servicio y su prueba de aceptación sin tocar el resto del flujo; si no hay tiempo, documentar el supuesto en el informe de cierre. | J7: Un docente observa o corrige un supuesto en G1, G2 o la entrega, o dos integrantes interpretan distinto uno de ellos. | K7: Héctor Sánchez | L7: Activa
A8: R07 | B8: Dado que cada integrante usa un agente y una herramienta distintos (OpenCode, Freebuff, Claude Code), puede ocurrir que cada módulo salga con estructura, estilo y pantallas distintas y la integración del Sprint 4 requiera rehacer código de dos o tres módulos para unificarlos. | C8: Proyecto | D8: 0.6 | E8: 2 | F8: =D8*E8 | G8: P: el plan lo reconoce como riesgo propio, los riesgos de estilo, UI e integración. Impacto: retrabajo acotado de 2 a 3 días si las reglas se verifican automáticamente. | H8: AGENTS.md único (S1-03) con estructura, estilo y componentes de UI compartidos, y esqueletos comunes (S1-05). La CI verifica lint, TypeScript strict e import-linter (D-04), así la inconsistencia se detecta en el PR y no en la integración. | I8: Unificar los componentes de UI repetidos (tablas, formularios, mensajes de error) y mover cada módulo al estilo del esqueleto. | J8: Dos módulos resuelven el mismo problema de forma distinta (formularios, manejo de errores) o el 21/10 la CI no verifica alguna regla de AGENTS.md. | K8: Joaquín Cardoso Díaz | L8: Activa
A10: R08 | B10: Dado que los agentes de IA generan funcionalidad con facilidad, puede ocurrir que implementen requerimientos que la consigna no pide (permisos, ABM extra, filtros) y se gaste tiempo de un sprint de una semana en código que nadie evalúa. | C10: Proyecto | D10: 0.5 | E10: 2 | F10: =D10*E10 | G10: P: el plan lo lista como riesgo del uso de IA. Impacto: se pierden 2 a 3 días de un módulo, con corrección simple (eliminar lo agregado). | H10: El checklist de PR incluye «nada que no esté en una HU o en el diagrama» y AGENTS.md prohíbe agregar funcionalidad no pedida. El revisor rechaza código sin criterio que lo respalde. | I10: Quitar lo extra del PR antes de mergear; si ya entró, revertirlo en un PR chico. | J10: Un PR agrega endpoints, pantallas o campos que no figuran en ninguna HU ni en el diagrama. | K10: Federico Cabaña | L10: Monitoreo
A11: R09 | B11: Dado que Producto, Mesa y Comanda las usan otros módulos (Reservas depende de Mesa y Comanda; Menús, Comandas y Facturas dependen de Producto), puede ocurrir que un cambio de atributos después de cerrar el diagrama rompa pruebas y código de los módulos que ya las usan. | C11: Proyecto | D11: 0.5 | E11: 2 | F11: =D11*E11 | G11: P: el diagrama ya está unificado pero la implementación puede mostrar atributos faltantes. Impacto: con agentes, actualizar tres módulos es retrabajo de 1 a 2 días. | H11: El diagrama unificado es la fuente: cualquier cambio entra por PR revisado por los dueños de los módulos que usan la clase y se avisa en la daily. Los atributos nuevos se agregan como opcionales. | I11: Hacer el cambio sin quitar lo existente (atributo nuevo opcional, migración Alembic) y actualizar los módulos afectados en el mismo PR. | J11: En el Sprint 2 o 3 hace falta agregar, quitar o renombrar un atributo de Producto, Mesa, Comanda o Cliente. | K11: Joaquín Cardoso Díaz | L11: Monitoreo
A12: R10 | B12: Dado que un producto puede estar en más de una promoción vigente (porcentaje, precio fijo o NxM) y el diagrama no fija una regla de prioridad, puede ocurrir que se aplique un descuento incorrecto o doble al pedir y la comanda y la factura salgan con un importe distinto al esperado. | C12: Negocio | D12: 0.5 | E12: 2 | F12: =D12*E12 | G12: P: los tres tipos tienen cálculo distinto y la regla de superposición no está decidida. Impacto: importe incorrecto en una comanda, con corrección posible desde la promoción sin rehacer HU. | H12: Fijar como supuesto que se aplica una sola promoción por producto (la de mayor descuento) y cubrir los tres tipos con casos de prueba, incluida la vigencia por día y hora. | I12: Finalizar la promoción en conflicto, corregir la función de cálculo y volver a probarla. | J12: Una prueba de descuento da un importe distinto al calculado a mano, o dos promociones vigentes coinciden sobre el mismo producto. | K12: Joaquín Cardoso Díaz | L12: Monitoreo
A13: R11 | B13: Dado que el estado de la Mesa lo cambia la Comanda (ocupar al abrirla, liberar al cerrarla o anularla) y que el mozo puede olvidar cerrar una comanda, puede ocurrir que una mesa quede OCUPADA sin que nadie la atienda, no se pueda asignar a nuevas comandas o reservas, y los reportes del turno incluyan comandas sin cerrar. | C13: Negocio | D13: 0.5 | E13: 2 | F13: =D13*E13 | G13: P: el olvido humano es habitual. Impacto: se resuelve cerrando la comanda a mano, sin afectar otras HU. | H13: La lógica de ocupar y liberar vive en un único servicio de Mesa que invoca Comanda (no se repite en las pantallas), con pruebas de cerrar y anular. El listado de comandas filtra las ABIERTAS y muestra su antigüedad. | I13: Cerrar o anular la comanda verificada y liberar la mesa desde la pantalla de Mesas. | J13: Al cerrar el turno hay una mesa OCUPADA sin comanda ABIERTA, o comandas abiertas hace más de 4 h. | K13: Juan Ignacio Riquelme | L13: Monitoreo
A14: R12 | B14: Dado que la factura copia precios y descuentos al emitirse y una comanda cerrada puede reabrirse, puede ocurrir que se reabra y modifique una comanda ya facturada y el importe de la comanda deje de coincidir con el de la factura. | C14: Técnico | D14: 0.5 | E14: 2 | F14: =D14*E14 | G14: P: la consigna no prohíbe reabrir una comanda facturada. Impacto: la diferencia se corrige a mano en datos, sin rehacer HU. | H14: Regla en el servicio: una comanda con factura no se puede reabrir ni modificar, con prueba en M4 y en M6. Se documenta como supuesto. | I14: Restaurar el detalle de la comanda desde el detalle de la factura, que conserva precios y descuentos. | J14: La suma del detalle de una comanda facturada difiere del total de su factura. | K14: Juan Ignacio Riquelme | L14: Monitoreo
... A25: R23 | B25: Dado que la carta debe mostrar fotos HEIC tomadas con el celular y los navegadores no muestran ese formato, puede ocurrir que la conversión a JPG falle o lleve más de lo previsto y las fotos no se vean en la carta. | C25: Técnico | D25: 0.3 | E25: 2 | F25: =D25*E25 | G25: Impacto: se puede aceptar solo JPG y PNG sin romper la HU. | H25: Al construir el alta de producto (Sprint 2), convertir HEIC a JPG en el servidor con una librería y probarlo con fotos reales de iPhone y de Android. | I25: Convertir la foto en el navegador antes de subirla, o aceptar solo JPG y PNG y documentar HEIC como limitación. | J25: En las pruebas del Sprint 2 una foto HEIC subida desde el celular no se ve en Chrome o la conversión falla. | K25: Franco Martín Soler | L25: Monitoreo

Sheet Línea de corte
A1: Línea de corte: qué riesgos gestionamos y por qué
A2: Esta hoja explica, en orden, cómo se decidió cuántos riesgos se gestionan activamente. Primero el resumen; abajo, los pasos y las cuentas.
A4: RESUMEN
A5: Riesgos identificados | B5: =COUNTIF(Riesgos!A:A,"R*")
A6: Con gestión activa (arriba de la línea) | B6: =COUNTIF(Riesgos!L:L,"Activa")
A7: En monitoreo (abajo de la línea) | B7: =COUNTIF(Riesgos!L:L,"Monitoreo")
A8: Parte de la exposición total que cubren los activos | B8: =SUMIF($F$46:$F$68,"Activa",$C$46:$C$68)/$C$69
A9: Máximo de riesgos activos que el equipo puede sostener | B9: =INT($B$22*$B$25*$B$18/($B$19+$B$20*$B$21))
A11: ="En una frase: gestionamos activamente "&B6&" de los "&B5&" riesgos, los de mayor exposición. Son los que el equipo puede seguir sin quitarle tiempo a la implementación; los otros "&B7&" quedan en monitoreo."
A12: Activo: tiene un responsable que revisa su disparador en cada daily y deja lista la mitigación desde ahora. Monitoreo: tiene su plan escrito, pero solo se mira en cada review de sprint; si se activa su disparador, pasa a activo.
A13: Exposición (E) = probabilidad × impacto. Es el número que ordena los riesgos: a mayor E, más conviene gestionarlo.
A16: PASO 1 · ¿Cuántos riesgos puede seguir el equipo?
A17: Gestionar un riesgo activamente cuesta horas: preparar su mitigación y su contingencia una vez, y revisar su disparador en cada sprint. Como los seis trabajan, esas horas no pueden quitarle tiempo a la implementación. Los valores azules son supuestos del equipo: si cambian, toda la hoja se recalcula.
A18: Integrantes del equipo | B18: 6 | C18: Franco, Joaquín, Giuliano, Juan, Federico y Héctor
A19: Horas para preparar cada riesgo (una vez) | B19: 2 | C19: Supuesto: dejar listas la mitigación y la contingencia
A20: Horas para vigilar cada riesgo, por sprint | B20: 0.5 | C20: Supuesto: revisar el disparador en la daily y en la review
A21: Sprints que quedan (Sprint 1 a Cierre) | B21: 5 | C21: Roadmap del plan de trabajo
A22: Tope de horas por persona y por semana | B22: 1.5 | C22: Supuesto: todos trabajan; el resto del tiempo es para implementar
A23: Fecha de hoy | B23: =DATE(2026,10,9)
A24: Fecha de entrega | B24: =DATE(2026,11,15) | C24: 15/11/2026, a confirmar con la cátedra
A25: Semanas que quedan | B25: =(B24-B23)/7 | C25: Se calcula con las dos fechas anteriores
A27: ¿Cuántos riesgos entran en ese tope? Cada fila supone gestionar esa cantidad de riesgos y calcula cuánto tiempo le pide a cada persona:
A28: Si gestionáramos… | C28: Horas del equipo hasta el cierre | D28: Horas por persona | E28: Horas por persona y por semana | F28: ¿Entra en el tope?
A29: 6 | C29: =A29*($B$19+$B$20*$B$21) | D29: =C29/$B$18 | E29: =D29/$B$25 | F29: =IF(E29<=$B$22,"Sí","No")
A30: 8 | C30: =A30*($B$19+$B$20*$B$21) | D30: =C30/$B$18 | E30: =D30/$B$25 | F30: =IF(E30<=$B$22,"Sí","No")
A31: 10 | C31: =A31*($B$19+$B$20*$B$21) | D31: =C31/$B$18 | E31: =D31/$B$25 | F31: =IF(E31<=$B$22,"Sí","No")
A32: 11 | C32: =A32*($B$19+$B$20*$B$21) | D32: =C32/$B$18 | E32: =D32/$B$25 | F32: =IF(E32<=$B$22,"Sí","No")
A33: 12 | C33: =A33*($B$19+$B$20*$B$21) | D33: =C33/$B$18 | E33: =D33/$B$25 | F33: =IF(E33<=$B$22,"Sí","No")
A34: 14 | C34: =A34*($B$19+$B$20*$B$21) | D34: =C34/$B$18 | E34: =D34/$B$25 | F34: =IF(E34<=$B$22,"Sí","No")
A35: 20 | C35: =A35*($B$19+$B$20*$B$21) | D35: =C35/$B$18 | E35: =D35/$B$25 | F35: =IF(E35<=$B$22,"Sí","No")
A37: PASO 2 · ¿Dónde se traza la línea?
A38: Con la capacidad del paso 1 entrarían hasta 10 riesgos. Pero la línea no se traza donde "queda lindo": se traza donde termina un grupo de riesgos con la misma exposición, para no separar riesgos que valen lo mismo. En la tabla de abajo, la columna «Cambio respecto del anterior» muestra esos escalones: cada vez que E baja, empieza un grupo nuevo. La línea roja queda en el último escalón que cabe dentro de la capacidad.
A40: PASO 3 · ¿Y qué dice Pareto?
A41: Pareto es la regla del 80/20: en muchos proyectos, unos pocos riesgos concentran la mayor parte del peligro, y alcanza con gestionar solo esos. Para comprobarlo se suma la exposición de los riesgos de mayor a menor y se mira en qué riesgo se llega al 80 % del total.
A42: Cómo leer la tabla: cada fila es un riesgo, del más expuesto al menos expuesto. «E» es probabilidad × impacto. «E acumulada» suma la E de esa fila y las anteriores. «% acumulado» es esa suma sobre el total de todos los riesgos. La línea roja marca el corte entre gestión activa y monitoreo.
A43: ="Resultado: los "&B6&" riesgos activos suman "&TEXT(B8,"0%")&" de la exposición total (celda amarilla: el 80 % recién se alcanza en el riesgo n.º "&(SUMPRODUCT(--(E46:E68<0.8))+1)&" de "&B5&"). Las exposiciones son parejas, así que Pareto no permite achicar la lista: gestionar el 80 % exigiría más riesgos de los que el equipo puede sostener ("&B9&" como máximo). Por eso el corte lo definen la capacidad (paso 1) y los grupos de igual E (paso 2)."
A45: Riesgo | B45: ID | C45: E (P × I) | D45: E acumulada | E45: % acumulado | F45: Gestión | G45: Cambio respecto del anterior
A46: Baja disponibilidad de un responsable de módulo | B46: =Riesgos!A2 | C46: =Riesgos!F2 | D46: =SUM($C$46:C46) | E46: =D46/$C$69 | F46: =Riesgos!L2
A47: Revisión superficial o tardía de los PR generados con IA | B47: =Riesgos!A3 | C47: =Riesgos!F3 | D47: =SUM($C$46:C47) | E47: =D47/$C$69 | F47: =Riesgos!L3 | G47: =IF(C46-C47<0.001,"","baja "&ROUND(C46-C47,1)&" · empieza otro grupo")
A48: Sprint 1 sobrecargado de tareas manuales y documentales | B48: =Riesgos!A4 | C48: =Riesgos!F4 | D48: =SUM($C$46:C48) | E48: =D48/$C$69 | F48: =Riesgos!L4 | G48: =IF(C47-C48<0.001,"","baja "&ROUND(C47-C48,1)&" · empieza otro grupo")
...

Sheet Escala
A1: Valor | B1: Criterio
A2: IMPACTO (I)
A3: 4 · Catastrófico | B3: No se entrega el sistema el 15/11, o se rompe un flujo central (comanda → factura → cobro) sin forma de evitarlo.
A4: 3 · Crítico | B4: Se pierde o hay que rehacer cerca de una semana de trabajo de una persona, queda sin entregar una HU obligatoria, o hay un defecto grave en una regla central (dinero, reservas).
A5: 2 · Marginal | B5: Retrabajo de hasta 2 o 3 días, o defecto en una HU con una forma manual simple de resolverlo.
A6: 1 · Despreciable | B6: Retrabajo de horas, sin efecto en la entrega.
A7: PROBABILIDAD (P)
A8: 0,7 o más | B8: Hay evidencia directa en el proyecto (algo ya pasó, o un documento lo afirma).
A9: 0,4 a 0,6 | B9: Es un problema habitual en equipos como este, sin evidencia directa.
A10: 0,3 o menos | B10: Poco probable por las decisiones ya tomadas (RNF, arquitectura, diagrama).
A11: CATEGORÍA
A12: Proyecto | B12: Amenaza el plan: cronograma, equipo, uso de IA, integración.
A13: Técnico | B13: Amenaza el producto: calidad, datos, tecnología elegida.
A14: Negocio | B14: Amenaza que el sistema cumpla lo que la cátedra y el restaurante simulado esperan.
A15: CONVENCIONES
A16: E = P × I | B16: Se ordena la tabla por E descendente; a igual E, primero el de mayor impacto.
A17: Disparador | B17: Condición observable que activa la contingencia, con fecha o hito cuando se puede.
A18: Responsable | B18: Integrante del equipo que vigila el disparador y ejecuta la contingencia.

Sheet Cambios
A1: Fila anterior | B1: ID anterior | C1: Riesgo anterior | D1: Decisión | E1: ID nuevo | F1: Motivo o destino
A2: 2 | B2: R09 | C2: Capacidad de mesa desincronizada con la realidad | D2: Descartado | E2: — | F2: La reserva no valida capacidad (decisión del diagrama: «sin límite de capacidad») y el responsable «Encargado» no es del equipo.
A3: 3 | B3: R05 | C3: Reservas depende de Mesa y Comanda | D3: Fusionado | E3: R09 | F3: Cambio de atributos en clases compartidas después del diagrama
A4: 4 | B4: R07 | C4: ¿La reserva requiere Cliente registrado? | D4: Resuelto | E4: — | F4: El diagrama lo definió: el cliente se crea junto con su primera reserva (Cliente 1..* Reserva).
A5: 5 | B5: R22 | C5: Superposición de responsabilidades entre integrantes | D5: Fusionado | E5: R07 | F5: Código y pantallas inconsistentes entre módulos
A6: 6 | B6: R24 | C6: Falta de estandarización de interfaces | D6: Fusionado | E6: R07 | F6: Código y pantallas inconsistentes entre módulos
A7: 7 | B7: R01 | C7: Atraso de comandas bloquea Reservas y Pagos | D7: Reformulado | E7: R04 | F7: Atraso de Comanda (M4) bloquea Reservas, Pagos y reportes
A8: 8 | B8: R04 | C8: Supuesto de mesa asignada manualmente | D8: Fusionado | E8: R06 | F8: Supuestos propios que la cátedra no confirma
A9: 9 | B9: R11 | C9: Cambio de atributos de Producto | D9: Fusionado | E9: R09 | F9: Cambio de atributos en clases compartidas después del diagrama
A10: 10 | B10: R19 | C10: Alcance ampliado con más funcionalidades | D10: Reformulado | E10: R08 | F10: Funcionalidad que la consigna no pide, agregada por el agente
A11: 11 | B11: R32 | C11: Comanda abierta por olvido del mozo | D11: Fusionado | E11: R11 | F11: Mesa OCUPADA sin atención real
A12: 12 | B12: R03 | C12: Formato poco práctico para mesas y sectores | D12: Descartado | E12: — | F12: No hay encargado real que valide prototipos; la usabilidad general se cubre con los estándares de UI (inconsistencia) y las reviews.
A13: 13 | B13: R21 | C13: Dificultad para integrar los módulos | D13: Fusionado | E13: R07 | F13: Código y pantallas inconsistentes entre módulos
... A35: 35 | B35: R02 | C35: Errores en el reporte de mesas y ventas por mozo | D35: Fusionado | E35: R19 | F35: Reportes con resultados que no coinciden con los datos
A37: Riesgos nuevos (7): disponibilidad, revisión de PR, Sprint 1 sobrecargado, supuestos (parte), cuota de IA, promociones superpuestas y fecha del 15/11. Salen del plan de trabajo (§4, §5, §8, §10). En la revisión del equipo se quitó el riesgo «Cierre de 4 días con entregables manuales» y se renumeraron los IDs.
A38: Se eliminaron las columnas «No» y «#GENERALIZAR» (notas sueltas), los IDs duplicados (R32 aparecía tres veces) y la fórmula cargada a mano en R15. Todas las E ahora son fórmulas. En la revisión del equipo también se quitaron las columnas #, Módulo y Origen.
